test_0 (__main__.lab4a.test_0)
[Lab 4] - [Investigation 1] - [Part 2] - Data Structures - Test for file creation: ./lab4a.py ... FAIL
test_a (__main__.lab4a.test_a)
[Lab 4] - [Investigation 1] - [Part 2] - Data Structures - Test for errors running: ./lab4a.py ... FAIL
test_a1 (__main__.lab4a.test_a1)
[Lab 4] - [Investigation 1] - [Part 2] - Data Structures - Test for correct shebang line: ./lab4a.py ... ERROR
test_a_function_join (__main__.lab4a.test_a_function_join)
[Lab 4] - [Investigation 1] - [Part 2] - Sets - function join_sets() fails without 2 arguments ... ok
test_b_function_join (__main__.lab4a.test_b_function_join)
[Lab 4] - [Investigation 1] - [Part 2] - Sets - function match_sets() fails without 2 arguments ... ok
test_c_function_join (__main__.lab4a.test_c_function_join)
[Lab 4] - [Investigation 1] - [Part 2] - Sets - function diff_sets() fails without 2 arguments ... ok
test_d_function_join_sets (__main__.lab4a.test_d_function_join_sets)
[Lab 4] - [Investigation 1] - [Part 2] - Sets - function join_sets() joins sets together {1,2,3,4,5} and {2,1,0,-1,-2} ... FAIL
test_e_function_join_sets (__main__.lab4a.test_e_function_join_sets)
[Lab 4] - [Investigation 1] - [Part 2] - Sets - function join_sets() joins sets together ... FAIL
test_f_function_match_sets (__main__.lab4a.test_f_function_match_sets)
[Lab 4] - [Investigation 1] - [Part 2] - Sets - function match_sets() ... FAIL
test_g_function_match_sets (__main__.lab4a.test_g_function_match_sets)
[Lab 4] - [Investigation 1] - [Part 2] - Sets - function match_sets() ... FAIL
test_h_function_diff_sets (__main__.lab4a.test_h_function_diff_sets)
[Lab 4] - [Investigation 1] - [Part 2] - Sets - function diff_sets() ... FAIL
test_i_function_diff_sets (__main__.lab4a.test_i_function_diff_sets)
[Lab 4] - [Investigation 1] - [Part 2] - Sets - function diff_sets() ... FAIL
test_0 (__main__.lab4b.test_0)
[Lab 4] - [Investigation 1] - [Part 2] - Data Structures - Test for file creation: ./lab4b.py ... FAIL
test_a (__main__.lab4b.test_a)
[Lab 4] - [Investigation 1] - [Part 2] - Data Structures - Test for errors running: ./lab4b.py ... FAIL
test_a1 (__main__.lab4b.test_a1)
[Lab 4] - [Investigation 1] - [Part 2] - Data Structures - Test for correct shebang line: ./lab4b.py ... ERROR
test_a_function_join (__main__.lab4b.test_a_function_join)
[Lab 4] - [Investigation 1] - [Part 2] - Sets - function join_lists() fails without 2 arguments ... ok
test_b_function_join (__main__.lab4b.test_b_function_join)
[Lab 4] - [Investigation 1] - [Part 2] - Sets - function match_lists() fails without 2 arguments ... ok
test_c_function_join (__main__.lab4b.test_c_function_join)
[Lab 4] - [Investigation 1] - [Part 2] - Sets - function diff_lists() fails without 2 arguments ... ok
test_d_function_join_lists (__main__.lab4b.test_d_function_join_lists)
[Lab 4] - [Investigation 1] - [Part 2] - Sets - function join_lists() joins lists together {1,2,3,4,5} and {2,1,0,-1,-2} ... FAIL
test_e_function_join_lists (__main__.lab4b.test_e_function_join_lists)
[Lab 4] - [Investigation 1] - [Part 2] - Sets - function join_lists() joins lists together ... FAIL
test_f_function_match_lists (__main__.lab4b.test_f_function_match_lists)
[Lab 4] - [Investigation 1] - [Part 2] - Sets - function match_lists() ... FAIL
test_g_function_match_lists (__main__.lab4b.test_g_function_match_lists)
[Lab 4] - [Investigation 1] - [Part 2] - Sets - function match_lists() ... FAIL
test_h_function_diff_lists (__main__.lab4b.test_h_function_diff_lists)
[Lab 4] - [Investigation 1] - [Part 2] - Sets - function diff_lists() ... FAIL
test_i_function_diff_lists (__main__.lab4b.test_i_function_diff_lists)
[Lab 4] - [Investigation 1] - [Part 2] - Sets - function diff_lists() ... FAIL
test_0 (__main__.lab4c.test_0)
[Lab 4] - [Investigation 1] - [Part 3] - Data Structures - Test for file creation: ./lab4c.py ... FAIL
test_a (__main__.lab4c.test_a)
[Lab 4] - [Investigation 1] - [Part 3] - Data Structures - Test for errors running: ./lab4c.py ... FAIL
test_a1 (__main__.lab4c.test_a1)
[Lab 4] - [Investigation 1] - [Part 3] - Data Structures - Test for correct shebang line: ./lab4c.py ... ERROR
test_b_function_create_dictionary (__main__.lab4c.test_b_function_create_dictionary)
[Lab 4] - [Investigation 1] - [Part 3] - Data Structures - function create_dictionary() fails without 2 arguments ... ok
test_d_function_shared_values (__main__.lab4c.test_d_function_shared_values)
[Lab 4] - [Investigation 1] - [Part 3] - Data Structures - function shared_values() fails without 2 arguments ... ok
test_e_function_create_dictionary (__main__.lab4c.test_e_function_create_dictionary)
[Lab 4] - [Investigation 1] - [Part 3] - Data Structures - function create_dictionary() ... FAIL
test_f_function_create_dictionary (__main__.lab4c.test_f_function_create_dictionary)
[Lab 4] - [Investigation 1] - [Part 3] - Data Structures - function create_dictionary() ... FAIL
test_i_function_split_dictionary (__main__.lab4c.test_i_function_split_dictionary)
[Lab 4] - [Investigation 1] - [Part 3] - Data Structures - function shared_values() ... FAIL
test_j_function_split_dictionary (__main__.lab4c.test_j_function_split_dictionary)
[Lab 4] - [Investigation 1] - [Part 3] - Data Structures - function shared_values() ... FAIL
test_0 (__main__.lab4d.test_0)
[Lab 4] - [Investigation 2] - [Part 1] - Strings - Test for file creation: ./lab4d.py ... FAIL
test_a (__main__.lab4d.test_a)
[Lab 4] - [Investigation 2] - [Part 1] - Strings - Test for errors running: ./lab4d.py ... FAIL
test_a1 (__main__.lab4d.test_a1)
[Lab 4] - [Investigation 2] - [Part 1] - Strings - Test for correct shebang line: ./lab4d.py ... ERROR
test_b_function_first_five (__main__.lab4d.test_b_function_first_five)
[Lab 4] - [Investigation 2] - [Part 1] - Strings - function first_five() ... FAIL
test_c_function_first_five (__main__.lab4d.test_c_function_first_five)
[Lab 4] - [Investigation 2] - [Part 1] - Strings - function first_five() ... FAIL
test_d_function_last_seven (__main__.lab4d.test_d_function_last_seven)
[Lab 4] - [Investigation 2] - [Part 1] - Strings - function last_seven() ... FAIL
test_e_function_last_seven (__main__.lab4d.test_e_function_last_seven)
[Lab 4] - [Investigation 2] - [Part 1] - Strings - function last_seven() ... FAIL
test_f_function_middle_number (__main__.lab4d.test_f_function_middle_number)
[Lab 4] - [Investigation 2] - [Part 1] - Strings - function middle_number() ... FAIL
test_g_function_middle_number (__main__.lab4d.test_g_function_middle_number)
[Lab 4] - [Investigation 2] - [Part 1] - Strings - function middle_number() ... FAIL
test_h_function_first_three_last_three (__main__.lab4d.test_h_function_first_three_last_three)
[Lab 4] - [Investigation 2] - [Part 1] - Strings - function first_three_last_three() ... FAIL
test_i_function_first_three_last_three (__main__.lab4d.test_i_function_first_three_last_three)
[Lab 4] - [Investigation 2] - [Part 1] - Strings - function first_three_last_three() ... FAIL
test_0 (__main__.lab4e.test_0)
[Lab 4] - [Investigation 2] - [Part 2] - Strings - Test for file creation: ./lab4e.py ... FAIL
test_a (__main__.lab4e.test_a)
[Lab 4] - [Investigation 2] - [Part 2] - Strings - Test for errors running: ./lab4e.py ... FAIL
test_a1 (__main__.lab4e.test_a1)
[Lab 4] - [Investigation 2] - [Part 2] - Strings - Test for correct shebang line: ./lab4e.py ... ERROR
test_b_function_is_digits (__main__.lab4e.test_b_function_is_digits)
[Lab 4] - [Investigation 2] - [Part 2] - Functions - is_digits("3058") has correct output ... FAIL
test_c_function_is_digits (__main__.lab4e.test_c_function_is_digits)
[Lab 4] - [Investigation 2] - [Part 2] - Functions - is_digits("x3058") has correct output ... FAIL
test_d_function_is_digits (__main__.lab4e.test_d_function_is_digits)
[Lab 4] - [Investigation 2] - [Part 2] - Functions - is_digits("8503x") has correct output ... FAIL
test_e_function_is_digits (__main__.lab4e.test_e_function_is_digits)
[Lab 4] - [Investigation 2] - [Part 2] - Functions - is_digits("8503") has correct output ... FAIL

======================================================================
ERROR: test_a1 (__main__.lab4a.test_a1)
[Lab 4] - [Investigation 1] - [Part 2] - Data Structures - Test for correct shebang line: ./lab4a.py
----------------------------------------------------------------------
Traceback (most recent call last):
  File "/home/elena/ops445/lab4/./CheckLab4.py", line 53, in test_a1
    lab_file = open('./lab4a.py')
               ^^^^^^^^^^^^^^^^^^
FileNotFoundError: [Errno 2] No such file or directory: './lab4a.py'

======================================================================
ERROR: test_a1 (__main__.lab4b.test_a1)
[Lab 4] - [Investigation 1] - [Part 2] - Data Structures - Test for correct shebang line: ./lab4b.py
----------------------------------------------------------------------
Traceback (most recent call last):
  File "/home/elena/ops445/lab4/./CheckLab4.py", line 171, in test_a1
    lab_file = open('./lab4b.py')
               ^^^^^^^^^^^^^^^^^^
FileNotFoundError: [Errno 2] No such file or directory: './lab4b.py'

======================================================================
ERROR: test_a1 (__main__.lab4c.test_a1)
[Lab 4] - [Investigation 1] - [Part 3] - Data Structures - Test for correct shebang line: ./lab4c.py
----------------------------------------------------------------------
Traceback (most recent call last):
  File "/home/elena/ops445/lab4/./CheckLab4.py", line 289, in test_a1
    lab_file = open('./lab4c.py')
               ^^^^^^^^^^^^^^^^^^
FileNotFoundError: [Errno 2] No such file or directory: './lab4c.py'

======================================================================
ERROR: test_a1 (__main__.lab4d.test_a1)
[Lab 4] - [Investigation 2] - [Part 1] - Strings - Test for correct shebang line: ./lab4d.py
----------------------------------------------------------------------
Traceback (most recent call last):
  File "/home/elena/ops445/lab4/./CheckLab4.py", line 413, in test_a1
    lab_file = open('./lab4d.py')
               ^^^^^^^^^^^^^^^^^^
FileNotFoundError: [Errno 2] No such file or directory: './lab4d.py'

======================================================================
ERROR: test_a1 (__main__.lab4e.test_a1)
[Lab 4] - [Investigation 2] - [Part 2] - Strings - Test for correct shebang line: ./lab4e.py
----------------------------------------------------------------------
Traceback (most recent call last):
  File "/home/elena/ops445/lab4/./CheckLab4.py", line 564, in test_a1
    lab_file = open('./lab4e.py')
               ^^^^^^^^^^^^^^^^^^
FileNotFoundError: [Errno 2] No such file or directory: './lab4e.py'

======================================================================
FAIL: test_0 (__main__.lab4a.test_0)
[Lab 4] - [Investigation 1] - [Part 2] - Data Structures - Test for file creation: ./lab4a.py
----------------------------------------------------------------------
Traceback (most recent call last):
  File "/home/elena/ops445/lab4/./CheckLab4.py", line 39, in test_0
    self.assertTrue(os.path.exists('./lab4a.py'), msg=error_output)
AssertionError: False is not true : your file cannot be found(HINT: make sure you AND your file are in the correct directory)

======================================================================
FAIL: test_a (__main__.lab4a.test_a)
[Lab 4] - [Investigation 1] - [Part 2] - Data Structures - Test for errors running: ./lab4a.py
----------------------------------------------------------------------
Traceback (most recent call last):
  File "/home/elena/ops445/lab4/./CheckLab4.py", line 49, in test_a
    self.assertEqual(return_code, 0, msg=error_output)
AssertionError: 2 != 0 : your program exited with a error(HINT: make sure you copied the script exactly!)

======================================================================
FAIL: test_d_function_join_sets (__main__.lab4a.test_d_function_join_sets)
[Lab 4] - [Investigation 1] - [Part 2] - Sets - function join_sets() joins sets together {1,2,3,4,5} and {2,1,0,-1,-2}
----------------------------------------------------------------------
Traceback (most recent call last):
  File "/home/elena/ops445/lab4/./CheckLab4.py", line 82, in test_d_function_join_sets
    import lab4a as lab4aStudent
ModuleNotFoundError: No module named 'lab4a'

During handling of the above exception, another exception occurred:

Traceback (most recent call last):
  File "/home/elena/ops445/lab4/./CheckLab4.py", line 84, in test_d_function_join_sets
    self.fail('lab4a.py contains errors(HINT: run the function and fix errors')
AssertionError: lab4a.py contains errors(HINT: run the function and fix errors

======================================================================
FAIL: test_e_function_join_sets (__main__.lab4a.test_e_function_join_sets)
[Lab 4] - [Investigation 1] - [Part 2] - Sets - function join_sets() joins sets together
----------------------------------------------------------------------
Traceback (most recent call last):
  File "/home/elena/ops445/lab4/./CheckLab4.py", line 94, in test_e_function_join_sets
    import lab4a as lab4aStudent
ModuleNotFoundError: No module named 'lab4a'

During handling of the above exception, another exception occurred:

Traceback (most recent call last):
  File "/home/elena/ops445/lab4/./CheckLab4.py", line 96, in test_e_function_join_sets
    self.fail('lab4a.py contains errors(HINT: run the function and fix errors')
AssertionError: lab4a.py contains errors(HINT: run the function and fix errors

======================================================================
FAIL: test_f_function_match_sets (__main__.lab4a.test_f_function_match_sets)
[Lab 4] - [Investigation 1] - [Part 2] - Sets - function match_sets()
----------------------------------------------------------------------
Traceback (most recent call last):
  File "/home/elena/ops445/lab4/./CheckLab4.py", line 106, in test_f_function_match_sets
    import lab4a as lab4aStudent
ModuleNotFoundError: No module named 'lab4a'

During handling of the above exception, another exception occurred:

Traceback (most recent call last):
  File "/home/elena/ops445/lab4/./CheckLab4.py", line 108, in test_f_function_match_sets
    self.fail('lab4a.py contains errors(HINT: run the function and fix errors')
AssertionError: lab4a.py contains errors(HINT: run the function and fix errors

======================================================================
FAIL: test_g_function_match_sets (__main__.lab4a.test_g_function_match_sets)
[Lab 4] - [Investigation 1] - [Part 2] - Sets - function match_sets()
----------------------------------------------------------------------
Traceback (most recent call last):
  File "/home/elena/ops445/lab4/./CheckLab4.py", line 118, in test_g_function_match_sets
    import lab4a as lab4aStudent
ModuleNotFoundError: No module named 'lab4a'

During handling of the above exception, another exception occurred:

Traceback (most recent call last):
  File "/home/elena/ops445/lab4/./CheckLab4.py", line 120, in test_g_function_match_sets
    self.fail('lab4a.py contains errors(HINT: run the function and fix errors')
AssertionError: lab4a.py contains errors(HINT: run the function and fix errors

======================================================================
FAIL: test_h_function_diff_sets (__main__.lab4a.test_h_function_diff_sets)
[Lab 4] - [Investigation 1] - [Part 2] - Sets - function diff_sets()
----------------------------------------------------------------------
Traceback (most recent call last):
  File "/home/elena/ops445/lab4/./CheckLab4.py", line 130, in test_h_function_diff_sets
    import lab4a as lab4aStudent
ModuleNotFoundError: No module named 'lab4a'

During handling of the above exception, another exception occurred:

Traceback (most recent call last):
  File "/home/elena/ops445/lab4/./CheckLab4.py", line 132, in test_h_function_diff_sets
    self.fail('lab4a.py contains errors(HINT: run the function and fix errors')
AssertionError: lab4a.py contains errors(HINT: run the function and fix errors

======================================================================
FAIL: test_i_function_diff_sets (__main__.lab4a.test_i_function_diff_sets)
[Lab 4] - [Investigation 1] - [Part 2] - Sets - function diff_sets()
----------------------------------------------------------------------
Traceback (most recent call last):
  File "/home/elena/ops445/lab4/./CheckLab4.py", line 142, in test_i_function_diff_sets
    import lab4a as lab4aStudent
ModuleNotFoundError: No module named 'lab4a'

During handling of the above exception, another exception occurred:

Traceback (most recent call last):
  File "/home/elena/ops445/lab4/./CheckLab4.py", line 144, in test_i_function_diff_sets
    self.fail('lab4a.py contains errors(HINT: run the function and fix errors')
AssertionError: lab4a.py contains errors(HINT: run the function and fix errors

======================================================================
FAIL: test_0 (__main__.lab4b.test_0)
[Lab 4] - [Investigation 1] - [Part 2] - Data Structures - Test for file creation: ./lab4b.py
----------------------------------------------------------------------
Traceback (most recent call last):
  File "/home/elena/ops445/lab4/./CheckLab4.py", line 157, in test_0
    self.assertTrue(os.path.exists('./lab4b.py'), msg=error_output)
AssertionError: False is not true : your file cannot be found(HINT: make sure you AND your file are in the correct directory)

======================================================================
FAIL: test_a (__main__.lab4b.test_a)
[Lab 4] - [Investigation 1] - [Part 2] - Data Structures - Test for errors running: ./lab4b.py
----------------------------------------------------------------------
Traceback (most recent call last):
  File "/home/elena/ops445/lab4/./CheckLab4.py", line 167, in test_a
    self.assertEqual(return_code, 0, msg=error_output)
AssertionError: 2 != 0 : your program exited with a error(HINT: make sure you copied the script exactly!)

======================================================================
FAIL: test_d_function_join_lists (__main__.lab4b.test_d_function_join_lists)
[Lab 4] - [Investigation 1] - [Part 2] - Sets - function join_lists() joins lists together {1,2,3,4,5} and {2,1,0,-1,-2}
----------------------------------------------------------------------
Traceback (most recent call last):
  File "/home/elena/ops445/lab4/./CheckLab4.py", line 200, in test_d_function_join_lists
    import lab4b as lab4bStudent
ModuleNotFoundError: No module named 'lab4b'

During handling of the above exception, another exception occurred:

Traceback (most recent call last):
  File "/home/elena/ops445/lab4/./CheckLab4.py", line 202, in test_d_function_join_lists
    self.fail('lab4b.py contains errors(HINT: run the function and fix errors')
AssertionError: lab4b.py contains errors(HINT: run the function and fix errors

======================================================================
FAIL: test_e_function_join_lists (__main__.lab4b.test_e_function_join_lists)
[Lab 4] - [Investigation 1] - [Part 2] - Sets - function join_lists() joins lists together
----------------------------------------------------------------------
Traceback (most recent call last):
  File "/home/elena/ops445/lab4/./CheckLab4.py", line 212, in test_e_function_join_lists
    import lab4b as lab4bStudent
ModuleNotFoundError: No module named 'lab4b'

During handling of the above exception, another exception occurred:

Traceback (most recent call last):
  File "/home/elena/ops445/lab4/./CheckLab4.py", line 214, in test_e_function_join_lists
    self.fail('lab4b.py contains errors(HINT: run the function and fix errors')
AssertionError: lab4b.py contains errors(HINT: run the function and fix errors

======================================================================
FAIL: test_f_function_match_lists (__main__.lab4b.test_f_function_match_lists)
[Lab 4] - [Investigation 1] - [Part 2] - Sets - function match_lists()
----------------------------------------------------------------------
Traceback (most recent call last):
  File "/home/elena/ops445/lab4/./CheckLab4.py", line 224, in test_f_function_match_lists
    import lab4b as lab4bStudent
ModuleNotFoundError: No module named 'lab4b'

During handling of the above exception, another exception occurred:

Traceback (most recent call last):
  File "/home/elena/ops445/lab4/./CheckLab4.py", line 226, in test_f_function_match_lists
    self.fail('lab4b.py contains errors(HINT: run the function and fix errors')
AssertionError: lab4b.py contains errors(HINT: run the function and fix errors

======================================================================
FAIL: test_g_function_match_lists (__main__.lab4b.test_g_function_match_lists)
[Lab 4] - [Investigation 1] - [Part 2] - Sets - function match_lists()
----------------------------------------------------------------------
Traceback (most recent call last):
  File "/home/elena/ops445/lab4/./CheckLab4.py", line 236, in test_g_function_match_lists
    import lab4b as lab4bStudent
ModuleNotFoundError: No module named 'lab4b'

During handling of the above exception, another exception occurred:

Traceback (most recent call last):
  File "/home/elena/ops445/lab4/./CheckLab4.py", line 238, in test_g_function_match_lists
    self.fail('lab4b.py contains errors(HINT: run the function and fix errors')
AssertionError: lab4b.py contains errors(HINT: run the function and fix errors

======================================================================
FAIL: test_h_function_diff_lists (__main__.lab4b.test_h_function_diff_lists)
[Lab 4] - [Investigation 1] - [Part 2] - Sets - function diff_lists()
----------------------------------------------------------------------
Traceback (most recent call last):
  File "/home/elena/ops445/lab4/./CheckLab4.py", line 248, in test_h_function_diff_lists
    import lab4b as lab4bStudent
ModuleNotFoundError: No module named 'lab4b'

During handling of the above exception, another exception occurred:

Traceback (most recent call last):
  File "/home/elena/ops445/lab4/./CheckLab4.py", line 250, in test_h_function_diff_lists
    self.fail('lab4b.py contains errors(HINT: run the function and fix errors')
AssertionError: lab4b.py contains errors(HINT: run the function and fix errors

======================================================================
FAIL: test_i_function_diff_lists (__main__.lab4b.test_i_function_diff_lists)
[Lab 4] - [Investigation 1] - [Part 2] - Sets - function diff_lists()
----------------------------------------------------------------------
Traceback (most recent call last):
  File "/home/elena/ops445/lab4/./CheckLab4.py", line 260, in test_i_function_diff_lists
    import lab4b as lab4bStudent
ModuleNotFoundError: No module named 'lab4b'

During handling of the above exception, another exception occurred:

Traceback (most recent call last):
  File "/home/elena/ops445/lab4/./CheckLab4.py", line 262, in test_i_function_diff_lists
    self.fail('lab4b.py contains errors(HINT: run the function and fix errors')
AssertionError: lab4b.py contains errors(HINT: run the function and fix errors

======================================================================
FAIL: test_0 (__main__.lab4c.test_0)
[Lab 4] - [Investigation 1] - [Part 3] - Data Structures - Test for file creation: ./lab4c.py
----------------------------------------------------------------------
Traceback (most recent call last):
  File "/home/elena/ops445/lab4/./CheckLab4.py", line 275, in test_0
    self.assertTrue(os.path.exists('./lab4c.py'), msg=error_output)
AssertionError: False is not true : your file cannot be found(HINT: make sure you AND your file are in the correct directory)

======================================================================
FAIL: test_a (__main__.lab4c.test_a)
[Lab 4] - [Investigation 1] - [Part 3] - Data Structures - Test for errors running: ./lab4c.py
----------------------------------------------------------------------
Traceback (most recent call last):
  File "/home/elena/ops445/lab4/./CheckLab4.py", line 285, in test_a
    self.assertEqual(return_code, 0, msg=error_output)
AssertionError: 2 != 0 : your program exited with a error(HINT: make sure you copied the script exactly!)

======================================================================
FAIL: test_e_function_create_dictionary (__main__.lab4c.test_e_function_create_dictionary)
[Lab 4] - [Investigation 1] - [Part 3] - Data Structures - function create_dictionary()
----------------------------------------------------------------------
Traceback (most recent call last):
  File "/home/elena/ops445/lab4/./CheckLab4.py", line 318, in test_e_function_create_dictionary
    import lab4c as lab4cStudent
ModuleNotFoundError: No module named 'lab4c'

During handling of the above exception, another exception occurred:

Traceback (most recent call last):
  File "/home/elena/ops445/lab4/./CheckLab4.py", line 320, in test_e_function_create_dictionary
    self.fail('lab4c.py contains errors(HINT: run the function and fix errors')
AssertionError: lab4c.py contains errors(HINT: run the function and fix errors

======================================================================
FAIL: test_f_function_create_dictionary (__main__.lab4c.test_f_function_create_dictionary)
[Lab 4] - [Investigation 1] - [Part 3] - Data Structures - function create_dictionary()
----------------------------------------------------------------------
Traceback (most recent call last):
  File "/home/elena/ops445/lab4/./CheckLab4.py", line 331, in test_f_function_create_dictionary
    import lab4c as lab4cStudent
ModuleNotFoundError: No module named 'lab4c'

During handling of the above exception, another exception occurred:

Traceback (most recent call last):
  File "/home/elena/ops445/lab4/./CheckLab4.py", line 333, in test_f_function_create_dictionary
    self.fail('lab4c.py contains errors(HINT: run the function and fix errors')
AssertionError: lab4c.py contains errors(HINT: run the function and fix errors

======================================================================
FAIL: test_i_function_split_dictionary (__main__.lab4c.test_i_function_split_dictionary)
[Lab 4] - [Investigation 1] - [Part 3] - Data Structures - function shared_values()
----------------------------------------------------------------------
Traceback (most recent call last):
  File "/home/elena/ops445/lab4/./CheckLab4.py", line 372, in test_i_function_split_dictionary
    import lab4c as lab4cStudent
ModuleNotFoundError: No module named 'lab4c'

During handling of the above exception, another exception occurred:

Traceback (most recent call last):
  File "/home/elena/ops445/lab4/./CheckLab4.py", line 374, in test_i_function_split_dictionary
    self.fail('lab4c.py contains errors(HINT: run the function and fix errors')
AssertionError: lab4c.py contains errors(HINT: run the function and fix errors

======================================================================
FAIL: test_j_function_split_dictionary (__main__.lab4c.test_j_function_split_dictionary)
[Lab 4] - [Investigation 1] - [Part 3] - Data Structures - function shared_values()
----------------------------------------------------------------------
Traceback (most recent call last):
  File "/home/elena/ops445/lab4/./CheckLab4.py", line 384, in test_j_function_split_dictionary
    import lab4c as lab4cStudent
ModuleNotFoundError: No module named 'lab4c'

During handling of the above exception, another exception occurred:

Traceback (most recent call last):
  File "/home/elena/ops445/lab4/./CheckLab4.py", line 386, in test_j_function_split_dictionary
    self.fail('lab4c.py contains errors(HINT: run the function and fix errors')
AssertionError: lab4c.py contains errors(HINT: run the function and fix errors

======================================================================
FAIL: test_0 (__main__.lab4d.test_0)
[Lab 4] - [Investigation 2] - [Part 1] - Strings - Test for file creation: ./lab4d.py
----------------------------------------------------------------------
Traceback (most recent call last):
  File "/home/elena/ops445/lab4/./CheckLab4.py", line 399, in test_0
    self.assertTrue(os.path.exists('./lab4d.py'), msg=error_output)
AssertionError: False is not true : your file cannot be found(HINT: make sure you AND your file are in the correct directory)

======================================================================
FAIL: test_a (__main__.lab4d.test_a)
[Lab 4] - [Investigation 2] - [Part 1] - Strings - Test for errors running: ./lab4d.py
----------------------------------------------------------------------
Traceback (most recent call last):
  File "/home/elena/ops445/lab4/./CheckLab4.py", line 409, in test_a
    self.assertEqual(return_code, 0, msg=error_output)
AssertionError: 2 != 0 : your program exited with a error(HINT: )

======================================================================
FAIL: test_b_function_first_five (__main__.lab4d.test_b_function_first_five)
[Lab 4] - [Investigation 2] - [Part 1] - Strings - function first_five()
----------------------------------------------------------------------
Traceback (most recent call last):
  File "/home/elena/ops445/lab4/./CheckLab4.py", line 423, in test_b_function_first_five
    import lab4d as lab4dStudent
ModuleNotFoundError: No module named 'lab4d'

During handling of the above exception, another exception occurred:

Traceback (most recent call last):
  File "/home/elena/ops445/lab4/./CheckLab4.py", line 425, in test_b_function_first_five
    self.fail('lab4d.py contains errors(HINT: run the function and fix errors')
AssertionError: lab4d.py contains errors(HINT: run the function and fix errors

======================================================================
FAIL: test_c_function_first_five (__main__.lab4d.test_c_function_first_five)
[Lab 4] - [Investigation 2] - [Part 1] - Strings - function first_five()
----------------------------------------------------------------------
Traceback (most recent call last):
  File "/home/elena/ops445/lab4/./CheckLab4.py", line 439, in test_c_function_first_five
    import lab4d as lab4dStudent
ModuleNotFoundError: No module named 'lab4d'

During handling of the above exception, another exception occurred:

Traceback (most recent call last):
  File "/home/elena/ops445/lab4/./CheckLab4.py", line 441, in test_c_function_first_five
    self.fail('lab4d.py contains errors(HINT: run the function and fix errors')
AssertionError: lab4d.py contains errors(HINT: run the function and fix errors

======================================================================
FAIL: test_d_function_last_seven (__main__.lab4d.test_d_function_last_seven)
[Lab 4] - [Investigation 2] - [Part 1] - Strings - function last_seven()
----------------------------------------------------------------------
Traceback (most recent call last):
  File "/home/elena/ops445/lab4/./CheckLab4.py", line 452, in test_d_function_last_seven
    import lab4d as lab4dStudent
ModuleNotFoundError: No module named 'lab4d'

During handling of the above exception, another exception occurred:

Traceback (most recent call last):
  File "/home/elena/ops445/lab4/./CheckLab4.py", line 454, in test_d_function_last_seven
    self.fail('lab4d.py contains errors(HINT: run the function and fix errors')
AssertionError: lab4d.py contains errors(HINT: run the function and fix errors

======================================================================
FAIL: test_e_function_last_seven (__main__.lab4d.test_e_function_last_seven)
[Lab 4] - [Investigation 2] - [Part 1] - Strings - function last_seven()
----------------------------------------------------------------------
Traceback (most recent call last):
  File "/home/elena/ops445/lab4/./CheckLab4.py", line 468, in test_e_function_last_seven
    import lab4d as lab4dStudent
ModuleNotFoundError: No module named 'lab4d'

During handling of the above exception, another exception occurred:

Traceback (most recent call last):
  File "/home/elena/ops445/lab4/./CheckLab4.py", line 470, in test_e_function_last_seven
    self.fail('lab4d.py contains errors(HINT: run the function and fix errors')
AssertionError: lab4d.py contains errors(HINT: run the function and fix errors

======================================================================
FAIL: test_f_function_middle_number (__main__.lab4d.test_f_function_middle_number)
[Lab 4] - [Investigation 2] - [Part 1] - Strings - function middle_number()
----------------------------------------------------------------------
Traceback (most recent call last):
  File "/home/elena/ops445/lab4/./CheckLab4.py", line 484, in test_f_function_middle_number
    import lab4d as lab4dStudent
ModuleNotFoundError: No module named 'lab4d'

During handling of the above exception, another exception occurred:

Traceback (most recent call last):
  File "/home/elena/ops445/lab4/./CheckLab4.py", line 486, in test_f_function_middle_number
    self.fail('lab4d.py contains errors(HINT: run the function and fix errors')
AssertionError: lab4d.py contains errors(HINT: run the function and fix errors

======================================================================
FAIL: test_g_function_middle_number (__main__.lab4d.test_g_function_middle_number)
[Lab 4] - [Investigation 2] - [Part 1] - Strings - function middle_number()
----------------------------------------------------------------------
Traceback (most recent call last):
  File "/home/elena/ops445/lab4/./CheckLab4.py", line 500, in test_g_function_middle_number
    import lab4d as lab4dStudent
ModuleNotFoundError: No module named 'lab4d'

During handling of the above exception, another exception occurred:

Traceback (most recent call last):
  File "/home/elena/ops445/lab4/./CheckLab4.py", line 502, in test_g_function_middle_number
    self.fail('lab4d.py contains errors(HINT: run the function and fix errors')
AssertionError: lab4d.py contains errors(HINT: run the function and fix errors

======================================================================
FAIL: test_h_function_first_three_last_three (__main__.lab4d.test_h_function_first_three_last_three)
[Lab 4] - [Investigation 2] - [Part 1] - Strings - function first_three_last_three()
----------------------------------------------------------------------
Traceback (most recent call last):
  File "/home/elena/ops445/lab4/./CheckLab4.py", line 516, in test_h_function_first_three_last_three
    import lab4d as lab4dStudent
ModuleNotFoundError: No module named 'lab4d'

During handling of the above exception, another exception occurred:

Traceback (most recent call last):
  File "/home/elena/ops445/lab4/./CheckLab4.py", line 518, in test_h_function_first_three_last_three
    self.fail('lab4d.py contains errors(HINT: run the function and fix errors')
AssertionError: lab4d.py contains errors(HINT: run the function and fix errors

======================================================================
FAIL: test_i_function_first_three_last_three (__main__.lab4d.test_i_function_first_three_last_three)
[Lab 4] - [Investigation 2] - [Part 1] - Strings - function first_three_last_three()
----------------------------------------------------------------------
Traceback (most recent call last):
  File "/home/elena/ops445/lab4/./CheckLab4.py", line 532, in test_i_function_first_three_last_three
    import lab4d as lab4dStudent
ModuleNotFoundError: No module named 'lab4d'

During handling of the above exception, another exception occurred:

Traceback (most recent call last):
  File "/home/elena/ops445/lab4/./CheckLab4.py", line 534, in test_i_function_first_three_last_three
    self.fail('lab4d.py contains errors(HINT: run the function and fix errors')
AssertionError: lab4d.py contains errors(HINT: run the function and fix errors

======================================================================
FAIL: test_0 (__main__.lab4e.test_0)
[Lab 4] - [Investigation 2] - [Part 2] - Strings - Test for file creation: ./lab4e.py
----------------------------------------------------------------------
Traceback (most recent call last):
  File "/home/elena/ops445/lab4/./CheckLab4.py", line 550, in test_0
    self.assertTrue(os.path.exists('./lab4e.py'), msg=error_output)
AssertionError: False is not true : your file cannot be found(HINT: make sure you AND your file are in the correct directory)

======================================================================
FAIL: test_a (__main__.lab4e.test_a)
[Lab 4] - [Investigation 2] - [Part 2] - Strings - Test for errors running: ./lab4e.py
----------------------------------------------------------------------
Traceback (most recent call last):
  File "/home/elena/ops445/lab4/./CheckLab4.py", line 560, in test_a
    self.assertEqual(return_code, 0, msg=error_output)
AssertionError: 2 != 0 : your program exited with a error(HINT: )

======================================================================
FAIL: test_b_function_is_digits (__main__.lab4e.test_b_function_is_digits)
[Lab 4] - [Investigation 2] - [Part 2] - Functions - is_digits("3058") has correct output
----------------------------------------------------------------------
Traceback (most recent call last):
  File "/home/elena/ops445/lab4/./CheckLab4.py", line 573, in test_b_function_is_digits
    import lab4e as lab4eStudent
ModuleNotFoundError: No module named 'lab4e'

During handling of the above exception, another exception occurred:

Traceback (most recent call last):
  File "/home/elena/ops445/lab4/./CheckLab4.py", line 575, in test_b_function_is_digits
    self.fail('lab4e.py contains errors (HINT: make sure you can import it.')
AssertionError: lab4e.py contains errors (HINT: make sure you can import it.

======================================================================
FAIL: test_c_function_is_digits (__main__.lab4e.test_c_function_is_digits)
[Lab 4] - [Investigation 2] - [Part 2] - Functions - is_digits("x3058") has correct output
----------------------------------------------------------------------
Traceback (most recent call last):
  File "/home/elena/ops445/lab4/./CheckLab4.py", line 583, in test_c_function_is_digits
    import lab4e as lab4eStudent
ModuleNotFoundError: No module named 'lab4e'

During handling of the above exception, another exception occurred:

Traceback (most recent call last):
  File "/home/elena/ops445/lab4/./CheckLab4.py", line 585, in test_c_function_is_digits
    self.fail('lab4e.py contains errors (HINT: make sure you can import it.')
AssertionError: lab4e.py contains errors (HINT: make sure you can import it.

======================================================================
FAIL: test_d_function_is_digits (__main__.lab4e.test_d_function_is_digits)
[Lab 4] - [Investigation 2] - [Part 2] - Functions - is_digits("8503x") has correct output
----------------------------------------------------------------------
Traceback (most recent call last):
  File "/home/elena/ops445/lab4/./CheckLab4.py", line 593, in test_d_function_is_digits
    import lab4e as lab4eStudent
ModuleNotFoundError: No module named 'lab4e'

During handling of the above exception, another exception occurred:

Traceback (most recent call last):
  File "/home/elena/ops445/lab4/./CheckLab4.py", line 595, in test_d_function_is_digits
    self.fail('lab4e.py contains errors (HINT: make sure you can import it.')
AssertionError: lab4e.py contains errors (HINT: make sure you can import it.

======================================================================
FAIL: test_e_function_is_digits (__main__.lab4e.test_e_function_is_digits)
[Lab 4] - [Investigation 2] - [Part 2] - Functions - is_digits("8503") has correct output
----------------------------------------------------------------------
Traceback (most recent call last):
  File "/home/elena/ops445/lab4/./CheckLab4.py", line 603, in test_e_function_is_digits
    import lab4e as lab4eStudent
ModuleNotFoundError: No module named 'lab4e'

During handling of the above exception, another exception occurred:

Traceback (most recent call last):
  File "/home/elena/ops445/lab4/./CheckLab4.py", line 605, in test_e_function_is_digits
    self.fail('lab4e.py contains errors (HINT: make sure you can import it.')
AssertionError: lab4e.py contains errors (HINT: make sure you can import it.

----------------------------------------------------------------------
Ran 51 tests in 0.063s

FAILED (failures=38, errors=5)
